<?xml version="1.0"?>
<!-- All measurement in URDF are in SI (i.e., distance = meters, angles = radians, weight = kg -->
<robot name="ai_rover"> 
  <material name="red">
    <color rgba="1.0 0.0 0.0 1"/>
  </material>

  <material name="green">
    <color rgba="0.0 1.0 0.0 1"/>
  </material>

  <material name="green_dark">
    <color rgba="0.0 0.5 0.0 1"/>
  </material>

  <material name="blue">
    <color rgba="0.0 0.0 1.0 1"/>
  </material>

  <material name="yellow">
    <color rgba="1.0 1.0 0.0 1"/>
  </material>

  <material name="black">
    <color rgba="0.0 0.0 0.0 1"/>
  </material>

  <material name="white">
    <color rgba="1.0 1.0 1.0 1"/>
  </material>

  <material name="box_bot_blue">
    <color rgba="0.088656 0.428691 0.491021 1"/>
  </material>
  <!-- 
    Using a first link named base_link is a best practice, but it can be empty.
    This is the root link, the parent from where all the links will hang. IT
    HAS TO BE UNIQUE
  -->
  <link name="base_link"/>

  <!-- Chasis represents the chasis of your bot. -->
  <link name="chassis">
    <visual>
      <geometry>
        <box size="0.220 0.105 0.05"/>
      </geometry>
      <material name="box_bot_blue"/>
    </visual>
    <collision>
      <origin xyz="0 0 0" rpy="0 0 0"/>
      <geometry>
        <box size="0.220 0.105 0.05"/>
      </geometry>
    </collision>
    <inertial>
      <mass value="5"/>
      <inertia ixx="0.13" ixy="0.0" ixz="0.0" iyy="0.21" iyz="0.0" izz="0.13"/>
    </inertial>
  </link>
  <!-- http://wiki.ros.org/urdf/XML/joint -->
  <joint name="base_link_joint" type="fixed">
    <origin rpy="0 0 0" xyz="0 0 0"/>
    <parent link="base_link"/>
    <child link="chassis"/>
  </joint>

  <!-- Right Wheel -->
  <link name="right_wheel">
    <visual>
      <origin xyz="0 0 0" rpy="1.570795 0 0"/>
      <geometry>
        <cylinder length="0.026" radius="0.033"/>
      </geometry>
      <material name="black"/>
    </visual>
    <collision>
      <origin xyz="0 0 0" rpy="1.570795 0 0"/>
      <geometry>
        <cylinder length="0.026" radius="0.033"/>
      </geometry>
    </collision>
    <inertial>
      <mass value="5"/>
      <inertia ixx="0.01" ixy="0.0" ixz="0.0" iyy="0.005" iyz="0.0" izz="0.005"/>
    </inertial>
  </link>
  <joint name="joint_right_wheel" type="continuous">
    <parent link="chassis"/>
    <child link="right_wheel"/>
    <origin xyz="0.025 -0.0675 -0.040" rpy="0 0 0"/>
    <axis xyz="0 1 0"/>
  </joint>

  <!-- Left Wheel -->
  <link name="left_wheel">
    <visual>
      <origin xyz="0 0 0" rpy="1.570795 0 0"/>
      <geometry>
        <cylinder length="0.026" radius="0.033"/>
      </geometry>
      <material name="white"/>
    </visual>
    <collision>
      <origin xyz="0 0 0" rpy="1.570795 0 0"/>
      <geometry>
        <cylinder length="0.026" radius="0.033"/>
      </geometry>
    </collision>
    <inertial>
      <mass value="5"/>
      <inertia ixx="0.01" ixy="0.0" ixz="0.0" iyy="0.005" iyz="0.0" izz="0.005"/>
    </inertial>
  </link>
  <joint name="joint_left_wheel" type="continuous">
    <parent link="chassis"/>
    <child link="left_wheel"/>
    <origin xyz="0.025 0.0675 -0.040" rpy="0 0 0"/>
    <axis xyz="0 1 0"/>
  </joint>

  <!-- Caster Wheel (Square Base)-->
  <link name="caster_base">
    <visual>
      <origin xyz="0 0 0" rpy="0 0 0"/>
      <geometry>
        <box size="0.025 0.025 0.030"/>
      </geometry>
      <material name="box_bot_blue"/>
    </visual>
    <collision>
      <origin xyz="0 0 0" rpy="0 0 0"/>
      <geometry>
        <box size="0.025 0.025 0.030"/>
      </geometry>
    </collision>
    <inertial>
      <mass value="5"/>
      <inertia ixx="0.13" ixy="0.0" ixz="0.0" iyy="0.21" iyz="0.0" izz="0.13"/>
    </inertial>
  </link>
  <joint name="caster_base" type="fixed">
    <parent link="chassis"/>
    <child link="caster_base"/>
    <origin xyz="-.097 0 -0.036" rpy="0 0 0"/>
  </joint>

  <!-- Caster Wheel (Back Sphere) -->
  <link name="back_yaw_link">
    <visual>
      <origin rpy="1.570795 0 0" xyz="0 0 0"/>
      <geometry>
        <cylinder length="0.001" radius="0.012"/>
      </geometry>
      <material name="blue"/>
    </visual>
    <collision>
      <origin rpy="1.570795 0 0" xyz="0 0 0"/>
      <geometry>
        <cylinder length="0.001" radius="0.012"/>
      </geometry>
    </collision>
    <inertial>
      <mass value="5"/>
      <inertia ixx="0.0001" ixy="0.0" ixz="0.0" iyy="0.0001" iyz="0.0" izz="0.0001"/>
    </inertial>
  </link>
  <joint name="back_yaw_joint" type="continuous">
    <origin rpy="0 0 0" xyz="0 0 -0.024"/>
    <parent link="caster_base"/>
    <child link="back_yaw_link"/>
    <axis xyz="0 0 1"/>
  </joint>

  <link name="back_roll_link">
    <visual>
      <origin rpy="1.570795 0 0" xyz="0 0 0"/>
      <geometry>
        <cylinder length="0.001" radius="0.012"/>
      </geometry>
      <material name="red"/>
    </visual>
    <collision>
      <origin rpy="1.570795 0 0" xyz="0 0 0"/>
      <geometry>
        <cylinder length="0.001" radius="0.012"/>
      </geometry>
    </collision>
    <inertial>
      <mass value="5"/>
      <inertia ixx="0.0001" ixy="0.0" ixz="0.0" iyy="0.0001" iyz="0.0" izz="0.0001"/>
    </inertial>
  </link>
  <joint name="back_roll_joint" type="continuous">
    <origin rpy="0 0 0" xyz="0 0 0"/>
    <parent link="back_yaw_link"/>
    <child link="back_roll_link"/>
    <axis xyz="1 0 0"/>
  </joint>

  <link name="back_pitch_link">
    <visual>
      <origin rpy="1.570795 0 0" xyz="0 0 0"/>
      <geometry>
        <sphere radius="0.012"/>
      </geometry>
      <material name="green"/>
    </visual>
    <collision>
      <origin rpy="1.570795 0 0" xyz="0 0 0"/>
      <geometry>
        <sphere radius="0.012"/>
      </geometry>
    </collision>
    <inertial>
      <mass value="5"/>
      <inertia ixx="0.0001" ixy="0.0" ixz="0.0" iyy="0.0001" iyz="0.0" izz="0.0001"/>
    </inertial>
  </link>
  <joint name="back_pitch_joint" type="continuous">
    <origin rpy="0 0 0" xyz="0 0 0"/>
    <parent link="back_roll_link"/>
    <child link="back_pitch_link"/>
    <axis xyz="0 1 0"/>
  </joint>
</robot>